Workbook

Sheet Справочник слов
A1: Слово | B1: Перевод | C1: Тип | D1: Сложность | E1: Тема
A2: kerb | B2: бордюр,ограничение | C2: существительное | D2: C2
A3: follower | B3: последователь | C3: существительное | D3: C2
A4: dim | B4: тусклый,слабый | C4: прилагательное | D4: C2
A5: hollow | B5: глухой (звук) | C5: прилагательное | D5: C2
A6: instinct | B6: инстинкт | C6: существительное | D6: C2
A7: to dread | B7: бояться,страшиться | C7: глагол | D7: C2
A8: conviction | B8: убеждение,признание виновным | C8: существительное | D8: C2
A9: to rot | B9: гнить | C9: глагол | D9: C2
A10: mercy | B10: пощада,милосердие | C10: существительное | D10: C2 | E10: Характер человека
A11: to giggle | B11: хихикать | C11: глагол | D11: C2 | E11: Действия человека
A12: to bind | B12: связывать,привязывать | C12: глагол | D12: C2
A13: to plead | B13: умолять,вымаливать | C13: глагол | D13: C2 | E13: Общение
A14: to retrieve | B14: извлекать,доставать | C14: глагол | D14: C2 | E14: Действия человека
A15: prime | B15: основной,главный | C15: прилагательное | D15: C2
A16: ritual | B16: ритуал,обряд | C16: существительное | D16: C2
A17: to suppress | B17: подавлять,сдерживать | C17: глагол | D17: C2
A18: resistance | B18: сопротивление,сопротивляемость | C18: существительное | D18: C2 | E18: Тело и здоровье
A19: intent | B19: намерение,умысел | C19: существительное | D19: C2
A20: civilian | B20: гражданское лицо,штатский | C20: существительное | D20: C2
A21: subtle | B21: тонкий,неуловимый | C21: прилагательное | D21: C2
A22: raid | B22: рейд,набег | C22: существительное | D22: C2
A23: knuckle | B23: костяшки пальцев | C23: существительное | D23: C2 | E23: Тело и здоровье
A24: wicked | B24: злой,безнравственный | C24: прилагательное | D24: C2 | E24: Характер человека
A25: scrap | B25: крохи,объедки | C25: существительное | D25: C2
A26: strand | B26: прядь,стренга | C26: существительное | D26: C2
A27: fireplace | B27: камин,очаг | C27: существительное | D27: C2
A28: to crumble | B28: крошить,крошиться | C28: глагол | D28: C2
A29: prey | B29: добыча,жертва | C29: существительное | D29: C2 | E29: Животные
A30: sorrow | B30: печаль,скорбь | C30: существительное | D30: C2 | E30: Характер человека
A31: heap | B31: куча,груда | C31: существительное | D31: C2
A32: globe | B32: глобус | C32: существительное | D32: C2
A33: pursuit | B33: погоня,преследование | C33: существительное | D33: C2
A34: wary | B34: осторожный,настороженный | C34: прилагательное | D34: C2 | E34: Характер человека
A35: to contemplate | B35: обдумывать,задумываться | C35: глагол | D35: C2
A36: strap | B36: ремешок,ремень | C36: существительное | D36: C2 | E36: Одежда
A37: lump | B37: комок | C37: существительное | D37: C2
A38: to yield | B38: уступать,производить | C38: глагол | D38: C2
A39: to loosen | B39: ослаблять | C39: глагол | D39: C2
A40: to flatten | B40: распластать,выравнивать | C40: глагол | D40: C2
...

Sheet Аналитика
A1: Аналитика справочника
A3: Всего записей | B3: =COUNTA('Справочник слов'!A2:A1000) -> 13823
A4: Уникальных слов | B4: =IFERROR(__xludf.DUMMYFUNCTION("COUNTUNIQUE(ARRAYFORMULA(LOWER(FILTER('Справочник слов'!A2:A1000,'Справочник слов'!A2:A1000<>""""))))"),13533.0) -> 13533
A6: Уровень | B6: Количество слов | D6: Тип | E6: Количество слов | G6: Тема | H6: Количество слов
A7: A1 | B7: =COUNTIF('Справочник слов'!D2:D1000,A7) -> 752 | D7: артикль | E7: =COUNTIF('Справочник слов'!C2:C1000,D7)+COUNTIF('Справочник слов'!C2:C1000,D7&", *")+COUNTIF('Справочник слов'!C2:C1000,"*, "&D7)+COUNTIF('Справочник слов'!C2:C1000,"*, "&D7&", *") -> 3 | G7: Внешность человека | H7: =COUNTIF('Справочник слов'!E2:E1000,G7)+COUNTIF('Справочник слов'!E2:E1000,G7&"; *")+COUNTIF('Справочник слов'!E2:E1000,"*; "&G7)+COUNTIF('Справочник слов'!E2:E1000,"*; "&G7&"; *") -> 120
A8: A2 | B8: =COUNTIF('Справочник слов'!D2:D1000,A8) -> 1206 | D8: глагол | E8: =COUNTIF('Справочник слов'!C2:C1000,D8)+COUNTIF('Справочник слов'!C2:C1000,D8&", *")+COUNTIF('Справочник слов'!C2:C1000,"*, "&D8)+COUNTIF('Справочник слов'!C2:C1000,"*, "&D8&", *") -> 2523 | G8: Действия человека | H8: =COUNTIF('Справочник слов'!E2:E1000,G8)+COUNTIF('Справочник слов'!E2:E1000,G8&"; *")+COUNTIF('Справочник слов'!E2:E1000,"*; "&G8)+COUNTIF('Справочник слов'!E2:E1000,"*; "&G8&"; *") -> 976
A9: B1 | B9: =COUNTIF('Справочник слов'!D2:D1000,A9) -> 2854 | D9: глагольная фраза | E9: =COUNTIF('Справочник слов'!C2:C1000,D9)+COUNTIF('Справочник слов'!C2:C1000,D9&", *")+COUNTIF('Справочник слов'!C2:C1000,"*, "&D9)+COUNTIF('Справочник слов'!C2:C1000,"*, "&D9&", *") -> 17 | G9: Деньги | H9: =COUNTIF('Справочник слов'!E2:E1000,G9)+COUNTIF('Справочник слов'!E2:E1000,G9&"; *")+COUNTIF('Справочник слов'!E2:E1000,"*; "&G9)+COUNTIF('Справочник слов'!E2:E1000,"*; "&G9&"; *") -> 240
A10: B2 | B10: =COUNTIF('Справочник слов'!D2:D1000,A10) -> 3956 | D10: грамматическая конструкция | E10: =COUNTIF('Справочник слов'!C2:C1000,D10)+COUNTIF('Справочник слов'!C2:C1000,D10&", *")+COUNTIF('Справочник слов'!C2:C1000,"*, "&D10)+COUNTIF('Справочник слов'!C2:C1000,"*, "&D10&", *") -> 1 | G10: Еда и напитки | H10: =COUNTIF('Справочник слов'!E2:E1000,G10)+COUNTIF('Справочник слов'!E2:E1000,G10&"; *")+COUNTIF('Справочник слов'!E2:E1000,"*; "&G10)+COUNTIF('Справочник слов'!E2:E1000,"*; "&G10&"; *") -> 325
A11: C1 | B11: =COUNTIF('Справочник слов'!D2:D1000,A11) -> 3197 | D11: междометие | E11: =COUNTIF('Справочник слов'!C2:C1000,D11)+COUNTIF('Справочник слов'!C2:C1000,D11&", *")+COUNTIF('Справочник слов'!C2:C1000,"*, "&D11)+COUNTIF('Справочник слов'!C2:C1000,"*, "&D11&", *") -> 14 | G11: Животные | H11: =COUNTIF('Справочник слов'!E2:E1000,G11)+COUNTIF('Справочник слов'!E2:E1000,G11&"; *")+COUNTIF('Справочник слов'!E2:E1000,"*; "&G11)+COUNTIF('Справочник слов'!E2:E1000,"*; "&G11&"; *") -> 126
A12: C2 | B12: =COUNTIF('Справочник слов'!D2:D1000,A12) -> 1858 | D12: местоимение | E12: =COUNTIF('Справочник слов'!C2:C1000,D12)+COUNTIF('Справочник слов'!C2:C1000,D12&", *")+COUNTIF('Справочник слов'!C2:C1000,"*, "&D12)+COUNTIF('Справочник слов'!C2:C1000,"*, "&D12&", *") -> 79 | G12: Искусство и медиа | H12: =COUNTIF('Справочник слов'!E2:E1000,G12)+COUNTIF('Справочник слов'!E2:E1000,G12&"; *")+COUNTIF('Справочник слов'!E2:E1000,"*; "&G12)+COUNTIF('Справочник слов'!E2:E1000,"*; "&G12&"; *") -> 335
D13: модальный глагол | E13: =COUNTIF('Справочник слов'!C2:C1000,D13)+COUNTIF('Справочник слов'!C2:C1000,D13&", *")+COUNTIF('Справочник слов'!C2:C1000,"*, "&D13)+COUNTIF('Справочник слов'!C2:C1000,"*, "&D13&", *") -> 7 | G13: Образование | H13: =COUNTIF('Справочник слов'!E2:E1000,G13)+COUNTIF('Справочник слов'!E2:E1000,G13&"; *")+COUNTIF('Справочник слов'!E2:E1000,"*; "&G13)+COUNTIF('Справочник слов'!E2:E1000,"*; "&G13&"; *") -> 163
D14: наречие | E14: =COUNTIF('Справочник слов'!C2:C1000,D14)+COUNTIF('Справочник слов'!C2:C1000,D14&", *")+COUNTIF('Справочник слов'!C2:C1000,"*, "&D14)+COUNTIF('Справочник слов'!C2:C1000,"*, "&D14&", *") -> 1113 | G14: Общение | H14: =COUNTIF('Справочник слов'!E2:E1000,G14)+COUNTIF('Справочник слов'!E2:E1000,G14&"; *")+COUNTIF('Справочник слов'!E2:E1000,"*; "&G14)+COUNTIF('Справочник слов'!E2:E1000,"*; "&G14&"; *") -> 819
D15: определитель | E15: =COUNTIF('Справочник слов'!C2:C1000,D15)+COUNTIF('Справочник слов'!C2:C1000,D15&", *")+COUNTIF('Справочник слов'!C2:C1000,"*, "&D15)+COUNTIF('Справочник слов'!C2:C1000,"*, "&D15&", *") -> 45 | G15: Одежда | H15: =COUNTIF('Справочник слов'!E2:E1000,G15)+COUNTIF('Справочник слов'!E2:E1000,G15&"; *")+COUNTIF('Справочник слов'!E2:E1000,"*; "&G15)+COUNTIF('Справочник слов'!E2:E1000,"*; "&G15&"; *") -> 132
D16: предлог | E16: =COUNTIF('Справочник слов'!C2:C1000,D16)+COUNTIF('Справочник слов'!C2:C1000,D16&", *")+COUNTIF('Справочник слов'!C2:C1000,"*, "&D16)+COUNTIF('Справочник слов'!C2:C1000,"*, "&D16&", *") -> 135 | G16: Отношения | H16: =COUNTIF('Справочник слов'!E2:E1000,G16)+COUNTIF('Справочник слов'!E2:E1000,G16&"; *")+COUNTIF('Справочник слов'!E2:E1000,"*; "&G16)+COUNTIF('Справочник слов'!E2:E1000,"*; "&G16&"; *") -> 180
D17: прилагательное | E17: =COUNTIF('Справочник слов'!C2:C1000,D17)+COUNTIF('Справочник слов'!C2:C1000,D17&", *")+COUNTIF('Справочник слов'!C2:C1000,"*, "&D17)+COUNTIF('Справочник слов'!C2:C1000,"*, "&D17&", *") -> 2636 | G17: Покупки | H17: =COUNTIF('Справочник слов'!E2:E1000,G17)+COUNTIF('Справочник слов'!E2:E1000,G17&"; *")+COUNTIF('Справочник слов'!E2:E1000,"*; "&G17)+COUNTIF('Справочник слов'!E2:E1000,"*; "&G17&"; *") -> 366
D18: приставка | E18: =COUNTIF('Справочник слов'!C2:C1000,D18)+COUNTIF('Справочник слов'!C2:C1000,D18&", *")+COUNTIF('Справочник слов'!C2:C1000,"*, "&D18)+COUNTIF('Справочник слов'!C2:C1000,"*, "&D18&", *") -> 3 | G18: Политика | H18: =COUNTIF('Справочник слов'!E2:E1000,G18)+COUNTIF('Справочник слов'!E2:E1000,G18&"; *")+COUNTIF('Справочник слов'!E2:E1000,"*; "&G18)+COUNTIF('Справочник слов'!E2:E1000,"*; "&G18&"; *") -> 104
D19: словосочетание | E19: =COUNTIF('Справочник слов'!C2:C1000,D19)+COUNTIF('Справочник слов'!C2:C1000,D19&", *")+COUNTIF('Справочник слов'!C2:C1000,"*, "&D19)+COUNTIF('Справочник слов'!C2:C1000,"*, "&D19&", *") -> 13 | G19: Природа | H19: =COUNTIF('Справочник слов'!E2:E1000,G19)+COUNTIF('Справочник слов'!E2:E1000,G19&"; *")+COUNTIF('Справочник слов'!E2:E1000,"*; "&G19)+COUNTIF('Справочник слов'!E2:E1000,"*; "&G19&"; *") -> 322
D20: сокращение | E20: =COUNTIF('Справочник слов'!C2:C1000,D20)+COUNTIF('Справочник слов'!C2:C1000,D20&", *")+COUNTIF('Справочник слов'!C2:C1000,"*, "&D20)+COUNTIF('Справочник слов'!C2:C1000,"*, "&D20&", *") -> 2 | G20: Путешествия | H20: =COUNTIF('Справочник слов'!E2:E1000,G20)+COUNTIF('Справочник слов'!E2:E1000,G20&"; *")+COUNTIF('Справочник слов'!E2:E1000,"*; "&G20)+COUNTIF('Справочник слов'!E2:E1000,"*; "&G20&"; *") -> 291
D21: союз | E21: =COUNTIF('Справочник слов'!C2:C1000,D21)+COUNTIF('Справочник слов'!C2:C1000,D21&", *")+COUNTIF('Справочник слов'!C2:C1000,"*, "&D21)+COUNTIF('Справочник слов'!C2:C1000,"*, "&D21&", *") -> 56 | G21: Работа | H21: =COUNTIF('Справочник слов'!E2:E1000,G21)+COUNTIF('Справочник слов'!E2:E1000,G21&"; *")+COUNTIF('Справочник слов'!E2:E1000,"*; "&G21)+COUNTIF('Справочник слов'!E2:E1000,"*; "&G21&"; *") -> 367
D22: суффикс | E22: =COUNTIF('Справочник слов'!C2:C1000,D22)+COUNTIF('Справочник слов'!C2:C1000,D22&", *")+COUNTIF('Справочник слов'!C2:C1000,"*, "&D22)+COUNTIF('Справочник слов'!C2:C1000,"*, "&D22&", *") -> 1 | G22: Тело и здоровье | H22: =COUNTIF('Справочник слов'!E2:E1000,G22)+COUNTIF('Справочник слов'!E2:E1000,G22&"; *")+COUNTIF('Справочник слов'!E2:E1000,"*; "&G22)+COUNTIF('Справочник слов'!E2:E1000,"*; "&G22&"; *") -> 430
D23: существительное | E23: =COUNTIF('Справочник слов'!C2:C1000,D23)+COUNTIF('Справочник слов'!C2:C1000,D23&", *")+COUNTIF('Справочник слов'!C2:C1000,"*, "&D23)+COUNTIF('Справочник слов'!C2:C1000,"*, "&D23&", *") -> 6076 | G23: Технологии | H23: =COUNTIF('Справочник слов'!E2:E1000,G23)+COUNTIF('Справочник слов'!E2:E1000,G23&"; *")+COUNTIF('Справочник слов'!E2:E1000,"*; "&G23)+COUNTIF('Справочник слов'!E2:E1000,"*; "&G23&"; *") -> 271
D24: фраза | E24: =COUNTIF('Справочник слов'!C2:C1000,D24)+COUNTIF('Справочник слов'!C2:C1000,D24&", *")+COUNTIF('Справочник слов'!C2:C1000,"*, "&D24)+COUNTIF('Справочник слов'!C2:C1000,"*, "&D24&", *") -> 57 | G24: Характер человека | H24: =COUNTIF('Справочник слов'!E2:E1000,G24)+COUNTIF('Справочник слов'!E2:E1000,G24&"; *")+COUNTIF('Справочник слов'!E2:E1000,"*; "&G24)+COUNTIF('Справочник слов'!E2:E1000,"*; "&G24&"; *") -> 972
D25: фразовый глагол | E25: =COUNTIF('Справочник слов'!C2:C1000,D25)+COUNTIF('Справочник слов'!C2:C1000,D25&", *")+COUNTIF('Справочник слов'!C2:C1000,"*, "&D25)+COUNTIF('Справочник слов'!C2:C1000,"*, "&D25&", *") -> 1074
D26: числительное | E26: =COUNTIF('Справочник слов'!C2:C1000,D26)+COUNTIF('Справочник слов'!C2:C1000,D26&", *")+COUNTIF('Справочник слов'!C2:C1000,"*, "&D26)+COUNTIF('Справочник слов'!C2:C1000,"*, "&D26&", *") -> 43
G30: Записи с несколькими темами учитываются в каждой категории.
D32: Записи с несколькими типами учитываются в каждой категории.
